INFO - 2024-12-29 21:57:34,161 - runserver - 7 - 133449100822208 - HTTP GET /admin/auth/user/ 200 [0.20, 172.29.0.1:53952]
INFO - 2024-12-29 21:57:34,386 - runserver - 7 - 133449100822208 - HTTP GET /static/admin/css/base.css 304 [0.01, 172.29.0.1:53952]
INFO - 2024-12-29 21:57:34,405 - runserver - 7 - 133449100822208 - HTTP GET /static/admin/css/dark_mode.css 304 [0.00, 172.29.0.1:53952]
INFO - 2024-12-29 21:57:34,436 - runserver - 7 - 133449100822208 - HTTP GET /static/admin/js/theme.js 304 [0.03, 172.29.0.1:53952]
INFO - 2024-12-29 21:57:34,457 - runserver - 7 - 133449100822208 - HTTP GET /static/admin/js/vendor/jquery/jquery.js 304 [0.02, 172.29.0.1:43276]
INFO - 2024-12-29 21:57:34,469 - runserver - 7 - 133449100822208 - HTTP GET /static/admin/css/nav_sidebar.css 304 [0.05, 172.29.0.1:43264]
INFO - 2024-12-29 21:57:34,471 - runserver - 7 - 133449100822208 - HTTP GET /static/admin/css/changelists.css 304 [0.04, 172.29.0.1:43290]
INFO - 2024-12-29 21:57:34,474 - runserver - 7 - 133449100822208 - HTTP GET /static/admin/js/nav_sidebar.js 304 [0.05, 172.29.0.1:43270]
INFO - 2024-12-29 21:57:34,486 - runserver - 7 - 133449100822208 - HTTP GET /static/admin/js/jquery.init.js 304 [0.03, 172.29.0.1:53952]
INFO - 2024-12-29 21:57:34,499 - runserver - 7 - 133449100822208 - HTTP GET /static/admin/js/core.js 304 [0.02, 172.29.0.1:43276]
INFO - 2024-12-29 21:57:34,526 - runserver - 7 - 133449100822208 - HTTP GET /static/admin/js/actions.js 304 [0.04, 172.29.0.1:43270]
INFO - 2024-12-29 21:57:34,527 - runserver - 7 - 133449100822208 - HTTP GET /static/admin/js/admin/RelatedObjectLookups.js 304 [0.04, 172.29.0.1:43264]
INFO - 2024-12-29 21:57:34,528 - runserver - 7 - 133449100822208 - HTTP GET /static/admin/js/urlify.js 304 [0.04, 172.29.0.1:43290]
INFO - 2024-12-29 21:57:34,529 - runserver - 7 - 133449100822208 - HTTP GET /static/admin/js/prepopulate.js 304 [0.04, 172.29.0.1:53952]
INFO - 2024-12-29 21:57:34,532 - runserver - 7 - 133449100822208 - HTTP GET /static/admin/js/vendor/xregexp/xregexp.js 304 [0.03, 172.29.0.1:43276]
INFO - 2024-12-29 21:57:34,580 - runserver - 7 - 133449100822208 - HTTP GET /static/admin/css/responsive.css 304 [0.04, 172.29.0.1:43264]
INFO - 2024-12-29 21:57:34,585 - runserver - 7 - 133449100822208 - HTTP GET /static/admin/js/filters.js 304 [0.04, 172.29.0.1:53952]
INFO - 2024-12-29 21:57:34,641 - runserver - 7 - 133449100822208 - HTTP GET /admin/jsi18n/ 200 [0.20, 172.29.0.1:43304]
INFO - 2024-12-29 21:57:35,081 - runserver - 7 - 133449100822208 - HTTP GET /static/admin/img/search.svg 200 [0.01, 172.29.0.1:53952]
INFO - 2024-12-29 21:57:35,097 - runserver - 7 - 133449100822208 - HTTP GET /static/admin/img/icon-yes.svg 200 [0.01, 172.29.0.1:43304]
INFO - 2024-12-29 21:57:35,098 - runserver - 7 - 133449100822208 - HTTP GET /static/admin/img/icon-addlink.svg 200 [0.01, 172.29.0.1:43270]
INFO - 2024-12-29 21:57:35,110 - runserver - 7 - 133449100822208 - HTTP GET /static/admin/img/tooltag-add.svg 200 [0.02, 172.29.0.1:43276]
INFO - 2024-12-29 21:57:35,111 - runserver - 7 - 133449100822208 - HTTP GET /static/admin/img/sorting-icons.svg 200 [0.02, 172.29.0.1:53952]
INFO - 2024-12-29 21:57:35,118 - runserver - 7 - 133449100822208 - HTTP GET /static/admin/img/icon-viewlink.svg 200 [0.02, 172.29.0.1:43290]
INFO - 2024-12-29 21:59:03,621 - runserver - 7 - 133449100822208 - HTTP GET /admin/auth/user/ 200 [0.03, 172.29.0.1:54524]
INFO - 2024-12-29 21:59:03,856 - runserver - 7 - 133449100822208 - HTTP GET /admin/jsi18n/ 200 [0.05, 172.29.0.1:54524]
INFO - 2024-12-29 23:13:35,310 - autoreload - 7 - 133449210166144 - /app/core/settings.py changed, reloading.
INFO - 2024-12-29 23:13:39,753 - autoreload - 71 - 129217347156864 - Watching for file changes with StatReloader
INFO - 2024-12-29 23:13:53,900 - autoreload - 71 - 129217347156864 - /app/core/settings.py changed, reloading.
INFO - 2024-12-29 23:13:55,994 - autoreload - 73 - 132716228672384 - Watching for file changes with StatReloader
INFO - 2024-12-29 23:15:15,632 - autoreload - 73 - 132716228672384 - /app/core/settings.py changed, reloading.
INFO - 2024-12-29 23:15:17,451 - autoreload - 75 - 129241142676352 - Watching for file changes with StatReloader
INFO - 2024-12-29 23:15:27,028 - autoreload - 75 - 129241142676352 - /app/core/settings.py changed, reloading.
INFO - 2024-12-29 23:15:29,321 - autoreload - 77 - 129582939462528 - Watching for file changes with StatReloader
INFO - 2024-12-29 23:15:49,345 - autoreload - 77 - 129582939462528 - /app/core/settings.py changed, reloading.
INFO - 2024-12-29 23:15:51,355 - autoreload - 79 - 127176492563328 - Watching for file changes with StatReloader
INFO - 2024-12-29 23:16:16,518 - autoreload - 79 - 127176492563328 - /app/core/settings.py changed, reloading.
INFO - 2024-12-29 23:16:18,706 - autoreload - 81 - 130981165157248 - Watching for file changes with StatReloader
INFO - 2024-12-29 23:16:28,838 - autoreload - 81 - 130981165157248 - /app/core/settings.py changed, reloading.
INFO - 2024-12-29 23:16:30,267 - autoreload - 83 - 125402461354880 - Watching for file changes with StatReloader
INFO - 2024-12-29 23:16:34,026 - runserver - 83 - 125402351666880 - HTTP GET /admin/auth/user/ 200 [0.30, 172.29.0.1:56136]
INFO - 2024-12-29 23:16:34,290 - runserver - 83 - 125402351666880 - HTTP GET /admin/jsi18n/ 200 [0.03, 172.29.0.1:36104]
WARNING - 2024-12-29 23:20:28,039 - log - 10 - 128710229362368 - Not Found: /
ERROR - 2024-12-29 23:21:16,590 - log - 11 - 140309038106304 - Internal Server Error: /admin/auth/user/
Traceback (most recent call last):
  File "/usr/local/lib/python3.12/site-packages/django/contrib/sessions/backends/base.py", line 244, in _get_session
    return self._session_cache
           ^^^^^^^^^^^^^^^^^^^
AttributeError: 'SessionStore' object has no attribute '_session_cache'

During handling of the above exception, another exception occurred:

Traceback (most recent call last):
  File "/usr/local/lib/python3.12/site-packages/django/db/backends/base/base.py", line 279, in ensure_connection
    self.connect()
  File "/usr/local/lib/python3.12/site-packages/django/utils/asyncio.py", line 26, in inner
    return func(*args, **kwargs)
           ^^^^^^^^^^^^^^^^^^^^^
  File "/usr/local/lib/python3.12/site-packages/django/db/backends/base/base.py", line 256, in connect
    self.connection = self.get_new_connection(conn_params)
                      ^^^^^^^^^^^^^^^^^^^^^^^^^^^^^^^^^^^^
  File "/usr/local/lib/python3.12/site-packages/dj_db_conn_pool/backends/postgresql/mixins.py", line 18, in get_new_connection
    connection = super().get_new_connection(conn_params)
                 ^^^^^^^^^^^^^^^^^^^^^^^^^^^^^^^^^^^^^^^
  File "/usr/local/lib/python3.12/site-packages/dj_db_conn_pool/core/mixins/core.py", line 106, in get_new_connection
    conn = db_pool.connect()
           ^^^^^^^^^^^^^^^^^
  File "/usr/local/lib/python3.12/site-packages/sqlalchemy/pool/base.py", line 449, in connect
    return _ConnectionFairy._checkout(self)
           ^^^^^^^^^^^^^^^^^^^^^^^^^^^^^^^^
  File "/usr/local/lib/python3.12/site-packages/sqlalchemy/pool/base.py", line 1263, in _checkout
    fairy = _ConnectionRecord.checkout(pool)
            ^^^^^^^^^^^^^^^^^^^^^^^^^^^^^^^^
  File "/usr/local/lib/python3.12/site-packages/sqlalchemy/pool/base.py", line 712, in checkout
    rec = pool._do_get()
          ^^^^^^^^^^^^^^
  File "/usr/local/lib/python3.12/site-packages/sqlalchemy/pool/impl.py", line 179, in _do_get
    with util.safe_reraise():
         ^^^^^^^^^^^^^^^^^^^
  File "/usr/local/lib/python3.12/site-packages/sqlalchemy/util/langhelpers.py", line 146, in __exit__
    raise exc_value.with_traceback(exc_tb)
  File "/usr/local/lib/python3.12/site-packages/sqlalchemy/pool/impl.py", line 177, in _do_get
    return self._create_connection()
           ^^^^^^^^^^^^^^^^^^^^^^^^^
  File "/usr/local/lib/python3.12/site-packages/sqlalchemy/pool/base.py", line 390, in _create_connection
    return _ConnectionRecord(self)
           ^^^^^^^^^^^^^^^^^^^^^^^
  File "/usr/local/lib/python3.12/site-packages/sqlalchemy/pool/base.py", line 674, in __init__
    self.__connect()
  File "/usr/local/lib/python3.12/site-packages/sqlalchemy/pool/base.py", line 900, in __connect
    with util.safe_reraise():
         ^^^^^^^^^^^^^^^^^^^
  File "/usr/local/lib/python3.12/site-packages/sqlalchemy/util/langhelpers.py", line 146, in __exit__
    raise exc_value.with_traceback(exc_tb)
  File "/usr/local/lib/python3.12/site-packages/sqlalchemy/pool/base.py", line 896, in __connect
    self.dbapi_connection = connection = pool._invoke_creator(self)
                                         ^^^^^^^^^^^^^^^^^^^^^^^^^^
  File "/usr/local/lib/python3.12/site-packages/sqlalchemy/pool/base.py", line 362, in <lambda>
    return lambda rec: creator_fn()
                       ^^^^^^^^^^^^
  File "/usr/local/lib/python3.12/site-packages/dj_db_conn_pool/core/mixins/core.py", line 90, in <lambda>
    lambda: self._get_new_connection(conn_params),
            ^^^^^^^^^^^^^^^^^^^^^^^^^^^^^^^^^^^^^
  File "/usr/local/lib/python3.12/site-packages/dj_db_conn_pool/core/mixins/core.py", line 45, in _get_new_connection
    return super().get_new_connection(conn_params)
           ^^^^^^^^^^^^^^^^^^^^^^^^^^^^^^^^^^^^^^^
  File "/usr/local/lib/python3.12/site-packages/django/utils/asyncio.py", line 26, in inner
    return func(*args, **kwargs)
           ^^^^^^^^^^^^^^^^^^^^^
  File "/usr/local/lib/python3.12/site-packages/django/db/backends/postgresql/base.py", line 332, in get_new_connection
    connection = self.Database.connect(**conn_params)
                 ^^^^^^^^^^^^^^^^^^^^^^^^^^^^^^^^^^^^
  File "/usr/local/lib/python3.12/site-packages/psycopg2/__init__.py", line 122, in connect
    conn = _connect(dsn, connection_factory=connection_factory, **kwasync)
           ^^^^^^^^^^^^^^^^^^^^^^^^^^^^^^^^^^^^^^^^^^^^^^^^^^^^^^^^^^^^^^^
psycopg2.OperationalError: could not translate host name "dfgdfg" to address: Temporary failure in name resolution


The above exception was the direct cause of the following exception:

Traceback (most recent call last):
  File "/usr/local/lib/python3.12/site-packages/asgiref/sync.py", line 518, in thread_handler
    raise exc_info[1]
  File "/usr/local/lib/python3.12/site-packages/django/core/handlers/exception.py", line 42, in inner
    response = await get_response(request)
               ^^^^^^^^^^^^^^^^^^^^^^^^^^^
  File "/usr/local/lib/python3.12/site-packages/asgiref/sync.py", line 518, in thread_handler
    raise exc_info[1]
  File "/usr/local/lib/python3.12/site-packages/django/core/handlers/base.py", line 253, in _get_response_async
    response = await wrapped_callback(
               ^^^^^^^^^^^^^^^^^^^^^^^
  File "/usr/local/lib/python3.12/site-packages/asgiref/sync.py", line 468, in __call__
    ret = await asyncio.shield(exec_coro)
          ^^^^^^^^^^^^^^^^^^^^^^^^^^^^^^^
  File "/usr/local/lib/python3.12/concurrent/futures/thread.py", line 59, in run
    result = self.fn(*self.args, **self.kwargs)
             ^^^^^^^^^^^^^^^^^^^^^^^^^^^^^^^^^^
  File "/usr/local/lib/python3.12/site-packages/asgiref/sync.py", line 522, in thread_handler
    return func(*args, **kwargs)
           ^^^^^^^^^^^^^^^^^^^^^
  File "/usr/local/lib/python3.12/site-packages/django/contrib/admin/options.py", line 718, in wrapper
    return self.admin_site.admin_view(view)(*args, **kwargs)
           ^^^^^^^^^^^^^^^^^^^^^^^^^^^^^^^^^^^^^^^^^^^^^^^^^
  File "/usr/local/lib/python3.12/site-packages/django/utils/decorators.py", line 188, in _view_wrapper
    result = _process_exception(request, e)
             ^^^^^^^^^^^^^^^^^^^^^^^^^^^^^^
  File "/usr/local/lib/python3.12/site-packages/django/utils/decorators.py", line 186, in _view_wrapper
    response = view_func(request, *args, **kwargs)
               ^^^^^^^^^^^^^^^^^^^^^^^^^^^^^^^^^^^
  File "/usr/local/lib/python3.12/site-packages/django/views/decorators/cache.py", line 80, in _view_wrapper
    response = view_func(request, *args, **kwargs)
               ^^^^^^^^^^^^^^^^^^^^^^^^^^^^^^^^^^^
  File "/usr/local/lib/python3.12/site-packages/django/contrib/admin/sites.py", line 229, in inner
    if not self.has_permission(request):
           ^^^^^^^^^^^^^^^^^^^^^^^^^^^^
  File "/usr/local/lib/python3.12/site-packages/django/contrib/admin/sites.py", line 202, in has_permission
    return request.user.is_active and request.user.is_staff
           ^^^^^^^^^^^^^^^^^^^^^^
  File "/usr/local/lib/python3.12/site-packages/django/utils/functional.py", line 251, in inner
    self._setup()
  File "/usr/local/lib/python3.12/site-packages/django/utils/functional.py", line 404, in _setup
    self._wrapped = self._setupfunc()
                    ^^^^^^^^^^^^^^^^^
  File "/usr/local/lib/python3.12/site-packages/django/contrib/auth/middleware.py", line 37, in <lambda>
    request.user = SimpleLazyObject(lambda: get_user(request))
                                            ^^^^^^^^^^^^^^^^^
  File "/usr/local/lib/python3.12/site-packages/django/contrib/auth/middleware.py", line 17, in get_user
    request._cached_user = auth.get_user(request)
                           ^^^^^^^^^^^^^^^^^^^^^^
  File "/usr/local/lib/python3.12/site-packages/django/contrib/auth/__init__.py", line 209, in get_user
    user_id = _get_user_session_key(request)
              ^^^^^^^^^^^^^^^^^^^^^^^^^^^^^^
  File "/usr/local/lib/python3.12/site-packages/django/contrib/auth/__init__.py", line 62, in _get_user_session_key
    return get_user_model()._meta.pk.to_python(request.session[SESSION_KEY])
                                               ~~~~~~~~~~~~~~~^^^^^^^^^^^^^
  File "/usr/local/lib/python3.12/site-packages/django/contrib/sessions/backends/base.py", line 55, in __getitem__
    return self._session[key]
           ^^^^^^^^^^^^^
  File "/usr/local/lib/python3.12/site-packages/django/contrib/sessions/backends/base.py", line 249, in _get_session
    self._session_cache = self.load()
                          ^^^^^^^^^^^
  File "/usr/local/lib/python3.12/site-packages/django/contrib/sessions/backends/db.py", line 55, in load
    s = self._get_session_from_db()
        ^^^^^^^^^^^^^^^^^^^^^^^^^^^
  File "/usr/local/lib/python3.12/site-packages/django/contrib/sessions/backends/db.py", line 34, in _get_session_from_db
    return self.model.objects.get(
           ^^^^^^^^^^^^^^^^^^^^^^^
  File "/usr/local/lib/python3.12/site-packages/django/db/models/manager.py", line 87, in manager_method
    return getattr(self.get_queryset(), name)(*args, **kwargs)
           ^^^^^^^^^^^^^^^^^^^^^^^^^^^^^^^^^^^^^^^^^^^^^^^^^^^
  File "/usr/local/lib/python3.12/site-packages/django/db/models/query.py", line 645, in get
    num = len(clone)
          ^^^^^^^^^^
  File "/usr/local/lib/python3.12/site-packages/django/db/models/query.py", line 382, in __len__
    self._fetch_all()
  File "/usr/local/lib/python3.12/site-packages/django/db/models/query.py", line 1928, in _fetch_all
    self._result_cache = list(self._iterable_class(self))
                         ^^^^^^^^^^^^^^^^^^^^^^^^^^^^^^^^
  File "/usr/local/lib/python3.12/site-packages/django/db/models/query.py", line 91, in __iter__
    results = compiler.execute_sql(
              ^^^^^^^^^^^^^^^^^^^^^
  File "/usr/local/lib/python3.12/site-packages/django/db/models/sql/compiler.py", line 1572, in execute_sql
    cursor = self.connection.cursor()
             ^^^^^^^^^^^^^^^^^^^^^^^^
  File "/usr/local/lib/python3.12/site-packages/django/utils/asyncio.py", line 26, in inner
    return func(*args, **kwargs)
           ^^^^^^^^^^^^^^^^^^^^^
  File "/usr/local/lib/python3.12/site-packages/django/db/backends/base/base.py", line 320, in cursor
    return self._cursor()
           ^^^^^^^^^^^^^^
  File "/usr/local/lib/python3.12/site-packages/django/db/backends/base/base.py", line 296, in _cursor
    self.ensure_connection()
  File "/usr/local/lib/python3.12/site-packages/django/utils/asyncio.py", line 26, in inner
    return func(*args, **kwargs)
           ^^^^^^^^^^^^^^^^^^^^^
  File "/usr/local/lib/python3.12/site-packages/django/db/backends/base/base.py", line 278, in ensure_connection
    with self.wrap_database_errors:
         ^^^^^^^^^^^^^^^^^^^^^^^^^
  File "/usr/local/lib/python3.12/site-packages/django/db/utils.py", line 91, in __exit__
    raise dj_exc_value.with_traceback(traceback) from exc_value
  File "/usr/local/lib/python3.12/site-packages/django/db/backends/base/base.py", line 279, in ensure_connection
    self.connect()
  File "/usr/local/lib/python3.12/site-packages/django/utils/asyncio.py", line 26, in inner
    return func(*args, **kwargs)
           ^^^^^^^^^^^^^^^^^^^^^
  File "/usr/local/lib/python3.12/site-packages/django/db/backends/base/base.py", line 256, in connect
    self.connection = self.get_new_connection(conn_params)
                      ^^^^^^^^^^^^^^^^^^^^^^^^^^^^^^^^^^^^
  File "/usr/local/lib/python3.12/site-packages/dj_db_conn_pool/backends/postgresql/mixins.py", line 18, in get_new_connection
    connection = super().get_new_connection(conn_params)
                 ^^^^^^^^^^^^^^^^^^^^^^^^^^^^^^^^^^^^^^^
  File "/usr/local/lib/python3.12/site-packages/dj_db_conn_pool/core/mixins/core.py", line 106, in get_new_connection
    conn = db_pool.connect()
           ^^^^^^^^^^^^^^^^^
  File "/usr/local/lib/python3.12/site-packages/sqlalchemy/pool/base.py", line 449, in connect
    return _ConnectionFairy._checkout(self)
           ^^^^^^^^^^^^^^^^^^^^^^^^^^^^^^^^
  File "/usr/local/lib/python3.12/site-packages/sqlalchemy/pool/base.py", line 1263, in _checkout
    fairy = _ConnectionRecord.checkout(pool)
            ^^^^^^^^^^^^^^^^^^^^^^^^^^^^^^^^
  File "/usr/local/lib/python3.12/site-packages/sqlalchemy/pool/base.py", line 712, in checkout
    rec = pool._do_get()
          ^^^^^^^^^^^^^^
  File "/usr/local/lib/python3.12/site-packages/sqlalchemy/pool/impl.py", line 179, in _do_get
    with util.safe_reraise():
         ^^^^^^^^^^^^^^^^^^^
  File "/usr/local/lib/python3.12/site-packages/sqlalchemy/util/langhelpers.py", line 146, in __exit__
    raise exc_value.with_traceback(exc_tb)
  File "/usr/local/lib/python3.12/site-packages/sqlalchemy/pool/impl.py", line 177, in _do_get
    return self._create_connection()
           ^^^^^^^^^^^^^^^^^^^^^^^^^
  File "/usr/local/lib/python3.12/site-packages/sqlalchemy/pool/base.py", line 390, in _create_connection
    return _ConnectionRecord(self)
           ^^^^^^^^^^^^^^^^^^^^^^^
  File "/usr/local/lib/python3.12/site-packages/sqlalchemy/pool/base.py", line 674, in __init__
    self.__connect()
  File "/usr/local/lib/python3.12/site-packages/sqlalchemy/pool/base.py", line 900, in __connect
    with util.safe_reraise():
         ^^^^^^^^^^^^^^^^^^^
  File "/usr/local/lib/python3.12/site-packages/sqlalchemy/util/langhelpers.py", line 146, in __exit__
    raise exc_value.with_traceback(exc_tb)
  File "/usr/local/lib/python3.12/site-packages/sqlalchemy/pool/base.py", line 896, in __connect
    self.dbapi_connection = connection = pool._invoke_creator(self)
                                         ^^^^^^^^^^^^^^^^^^^^^^^^^^
  File "/usr/local/lib/python3.12/site-packages/sqlalchemy/pool/base.py", line 362, in <lambda>
    return lambda rec: creator_fn()
                       ^^^^^^^^^^^^
  File "/usr/local/lib/python3.12/site-packages/dj_db_conn_pool/core/mixins/core.py", line 90, in <lambda>
    lambda: self._get_new_connection(conn_params),
            ^^^^^^^^^^^^^^^^^^^^^^^^^^^^^^^^^^^^^
  File "/usr/local/lib/python3.12/site-packages/dj_db_conn_pool/core/mixins/core.py", line 45, in _get_new_connection
    return super().get_new_connection(conn_params)
           ^^^^^^^^^^^^^^^^^^^^^^^^^^^^^^^^^^^^^^^
  File "/usr/local/lib/python3.12/site-packages/django/utils/asyncio.py", line 26, in inner
    return func(*args, **kwargs)
           ^^^^^^^^^^^^^^^^^^^^^
  File "/usr/local/lib/python3.12/site-packages/django/db/backends/postgresql/base.py", line 332, in get_new_connection
    connection = self.Database.connect(**conn_params)
                 ^^^^^^^^^^^^^^^^^^^^^^^^^^^^^^^^^^^^
  File "/usr/local/lib/python3.12/site-packages/psycopg2/__init__.py", line 122, in connect
    conn = _connect(dsn, connection_factory=connection_factory, **kwasync)
           ^^^^^^^^^^^^^^^^^^^^^^^^^^^^^^^^^^^^^^^^^^^^^^^^^^^^^^^^^^^^^^^
django.db.utils.OperationalError: could not translate host name "dfgdfg" to address: Temporary failure in name resolution

WARNING - 2024-12-29 23:37:37,463 - log - 11 - 132352927860416 - Not Found: /static/admin/js/filters.js
INFO - 2024-12-29 23:38:43,577 - autoreload - 7 - 140712702950272 - Watching for file changes with StatReloader
INFO - 2024-12-29 23:40:05,528 - autoreload - 7 - 140712702950272 - /app/core/settings.py changed, reloading.
INFO - 2024-12-29 23:40:07,720 - autoreload - 9 - 132794648501120 - Watching for file changes with StatReloader
INFO - 2024-12-29 23:40:13,450 - runserver - 9 - 132794539837120 - HTTP GET /admin/auth/user/ 200 [0.31, 192.168.64.1:52280]
INFO - 2024-12-29 23:40:13,725 - runserver - 9 - 132794539837120 - HTTP GET /admin/jsi18n/ 200 [0.03, 192.168.64.1:52280]
INFO - 2024-12-29 23:40:50,575 - autoreload - 9 - 132794648501120 - /app/core/settings.py changed, reloading.
INFO - 2024-12-29 23:40:52,395 - autoreload - 14 - 134133344287616 - Watching for file changes with StatReloader
INFO - 2024-12-29 23:41:14,477 - autoreload - 14 - 134133344287616 - /app/core/settings.py changed, reloading.
INFO - 2024-12-29 23:41:16,752 - autoreload - 16 - 125264180403072 - Watching for file changes with StatReloader
INFO - 2024-12-29 23:41:50,318 - autoreload - 7 - 128989727234944 - Watching for file changes with StatReloader
INFO - 2024-12-29 23:42:11,654 - autoreload - 7 - 128989727234944 - /app/core/settings.py changed, reloading.
INFO - 2024-12-29 23:42:13,515 - autoreload - 9 - 131557398412160 - Watching for file changes with StatReloader
INFO - 2024-12-29 23:42:40,833 - autoreload - 9 - 131557398412160 - /app/core/settings.py changed, reloading.
INFO - 2024-12-29 23:42:42,994 - autoreload - 11 - 124049353161600 - Watching for file changes with StatReloader
INFO - 2024-12-29 23:43:55,646 - autoreload - 7 - 137565913435008 - Watching for file changes with StatReloader
INFO - 2024-12-29 23:44:09,758 - autoreload - 7 - 137565913435008 - /app/core/settings.py changed, reloading.
INFO - 2024-12-29 23:44:11,933 - autoreload - 9 - 123421056056192 - Watching for file changes with StatReloader
INFO - 2024-12-29 23:46:47,020 - autoreload - 6 - 131744680934272 - Watching for file changes with StatReloader
INFO - 2024-12-29 23:46:59,906 - autoreload - 6 - 131744680934272 - /app/core/settings.py changed, reloading.
INFO - 2024-12-29 23:47:02,214 - autoreload - 8 - 130324096019328 - Watching for file changes with StatReloader
INFO - 2024-12-29 23:54:43,975 - autoreload - 6 - 129679917894528 - Watching for file changes with StatReloader
INFO - 2024-12-29 23:55:05,721 - runserver - 6 - 129679809840832 - HTTP GET /admin/auth/user/ 200 [0.21, 192.168.128.1:56264]
INFO - 2024-12-29 23:55:05,937 - runserver - 6 - 129679809840832 - HTTP GET /static/admin/js/filters.js 200 [0.01, 192.168.128.1:56286]
INFO - 2024-12-29 23:55:05,949 - runserver - 6 - 129679809840832 - HTTP GET /admin/jsi18n/ 200 [0.05, 192.168.128.1:56264]
INFO - 2024-12-29 23:55:07,581 - runserver - 6 - 129679809840832 - HTTP GET /admin/auth/user/ 200 [0.04, 192.168.128.1:56286]
INFO - 2024-12-29 23:55:07,829 - runserver - 6 - 129679809840832 - HTTP GET /admin/jsi18n/ 200 [0.05, 192.168.128.1:56286]
